---
title: 15.1 错误与异常
date: 2022-03-04 14:51:47
categories: 测试学习
tags: [python编程语言]
---



# 1 语法错误与定位

## 错误

- 语法错误
- 逻辑错误
- 系统错误

## 异常

- 程序执行过程中出现的未知错误
- 语法和逻辑都是正常的
- 程序业务逻辑不完善引起的程序漏洞（bug）

## **错误与异常的区别？**

- 异常可以被捕获和处理
- 错误一般是编码错误，逻辑错误，系统错误

## 异常/错误处理流程

<img src="15-1-错误与异常/image-20220304192005145.png" alt="image-20220304192005145" style="zoom:50%;" />

- 如果是拼写、配置等引起的错误，根据出错信息排查错误出现的位置进行解决
- 如果是程序设计不完善引起的漏洞，根据漏洞的情况进行设计处理漏洞的逻辑

## 常见的异常类型

- 异常类型：https://docs.python.org/3/library/exceptions.html#bltin-exceptions

- 常见的异常类型：

    - 除零类型

        ​	除数为0

    - 名称异常

        ​	例如：参数未定义

    - 索引异常

        ​	例如：列表或元组索引超出范围

    - 键异常

        ​	例如：字典取值时没有键

    - 值异常

        ​	例如：传入和输出的类型不一致

    - 属性异常

        ​	例如：在python中有一些常量属性值，更新时发生的异常



# 2 异常捕获&异常处理

`try/except`语句用来检测`try`语句块中的错误，从而让`except`语句捕获异常信息并处理。

如果不想在异常发生时结束程序，只需在`try`里捕获它。

例子：

```python
def js(a, b):
    return a / b


try:
    print(js(1, 1))
    list1 = [1, 2, 3]
    print(list1[3])
except ZeroDivisionError as e:
    print(e)
    print('这里有一个异常')
except IndexError as c:
    print(c)
```

结果：

```python
1.0
list index out of range
```

当然一个一个异常去处理比较麻烦，可以改写程序：

```python
except Exception as exception:
    print(exception)
```

> Exception是大多数异常的父类，BaseException是所有异常的父类。

## 方法1

```python
try:
	执行代码
except:
	发生异常时执行的代码
```

## 方法2

```python
try:
	执行代码
except:
	发生异常时执行的代码
else:
    没有异常时执行的代码
```

## 方法3

```python
try:
	执行代码
except:
	发生异常时执行的代码
else:
    没有异常时执行的代码
finally:
    不管有没有异常都会执行的代码
```

## 方法4 手动引发异常`raise`

系统的自带的异常只要触发会自动抛出，比如`NameError`，但用户自定义的异常需要用户自己决定什么时候抛出。 `raise` 唯一的一个参数指定了要被抛出的异常。它必须是一个异常的实例或者是异常的类（也就是 `Exception` 的子类）。大多数的异常的名字都以"`Error`"结尾，所以实际命名时尽量跟标准的异常命名一样。

raise 语句的基本语法格式为：`raise [exceptionName [(reason)]]`

其中，用 `[]` 括起来的为可选参数，其作用是指定抛出的异常名称，以及异常信息的相关描述。如果可选参数全部省略，则 raise 会把当前错误原样抛出；如果仅省略 `(reason)`，则在抛出异常时，将不附带任何的异常描述信息。

也就是说，raise 语句有如下三种常用的用法：

- `raise`：单独一个 raise。该语句引发当前上下文中捕获的异常（比如在 except 块中），或默认引发 RuntimeError 异常。
- `raise 异常类名称`：raise 后带一个异常类名称，表示引发执行类型的异常。
- `raise 异常类名称(描述信息)`：在引发指定类型的异常的同时，附带异常的描述信息。

```python
try:
    a = input("输入一个数：")
    # 判断用户输入的是否为数字
    if not a.isdigit():
        raise ValueError("a 必须是数字")
except ValueError as e:
    # repr函数，返回对象的规范字符串表示
    print("引发异常：", repr(e))
```

输入`a`，结果：

```python
输入一个数：a
引发异常： ValueError('a 必须是数字')
```

可以看到，当用户输入的不是数字时，程序会进入 `if` 判断语句，并执行 `raise` 引发 `ValueError` 异常。但由于其位于 try 块中，因为 `raise` 抛出的异常会被 `try` 捕获，并由 `except` 块进行处理。

因此，虽然程序中使用了 `raise` 语句引发异常，但程序的执行是正常的，手动抛出的异常并不会导致程序崩溃。

# 3 自定义异常

通过创建一个新的异常类，程序可以命名它们自己的异常。异常应该是典型的继承自<font color='red'>Exception</font>类，通过直接或间接的方式。

## 3.1 手动抛出异常

```python
# 1.用户自定义异常类型，继承自Exception类
class TooLongException(Exception):

    def __init__(self, le):
        self.le = le

    def __str__(self):
        print(f"姓名长度是{self.le}，超过长度了")


# 2.手动抛出用户自定义类型异常
def nameTest():
    name = input("enter your name:")
    if len(name) > 4:
        raise TooLongException(len(name))  # 抛出异常很简单，使用raise即可,但是没有处理，即捕捉
    else:
        print(name)


# 调用函数，执行
nameTest()
```

结果：

```python
enter your name:t43rtfdvcx
姓名长度是10，超过长度了
Traceback (most recent call last):
  File "D:\PycharmProject\error.py", line 74, in <module>
    nameTest()
  File "D:\PycharmProject\error.py", line 68, in nameTest
    raise TooLongException(len(name))  # 抛出异常很简单，使用raise即可,但是没有处理，即捕捉
__main__.TooLongException: <exception str() failed>
```

## 3.2 捕捉用户手动抛出的异常

```python
# 1.用户自定义异常类型，继承自Exception类
class TooLongException(Exception):

    def __init__(self, le):
        self.le = le

    def __str__(self):
        print(f"姓名长度是{self.le}，超过长度了")


# 2.捕捉用户手动抛出的异常，跟捕捉系统异常方式一样
def nameTest():
    try:
        name = input("enter your name:")
        if len(name) > 4:
            raise TooLongException(len(name))
        else:
            print(name)
    except TooLongException as e_result:  # 这里异常类型是用户自定义的
        print("捕捉到异常了")
        print("打印异常信息：", e_result)


# 调用函数，执行
nameTest()
```

结果：

```python
enter your name:rytgfd2q345
捕捉到异常了
Traceback (most recent call last):
  File "D:\PycharmProject\error.py", line 93, in nameTest
    raise TooLongException(len(name))
__main__.TooLongException: <exception str() failed>

During handling of the above exception, another exception occurred:

Traceback (most recent call last):
  File "D:\PycharmProject\error.py", line 102, in <module>
    nameTest()
  File "D:\PycharmProject\error.py", line 98, in nameTest
    print("打印异常信息：", e_result)
TypeError: __str__ returned non-string (type NoneType)
打印异常信息： 姓名长度是11，超过长度了
姓名长度是11，超过长度了

进程已结束,退出代码1
```

